<?xml version="1.0"?>
<robot xmlns:xacro="http://www.ros.org/wiki/xacro">
  <xacro:macro name="ur3_gripper" params="prefix parent *origin">
    <joint name="${prefix}gripper_base_joint" type="fixed">
      <parent link="${parent}"/>
      <child link="${prefix}gripper_base_link"/>
      <xacro:insert_block name="origin"/>
    </joint>

    <link name="${prefix}gripper_base_link">
      <visual>
        <geometry>
          <box size="0.02 0.02 0.02"/>
        </geometry>
        <material name="blue">
          <color rgba="0 0 0.8 1"/>
        </material>
      </visual>
      <collision>
        <geometry>
          <box size="0.02 0.02 0.02"/>
        </geometry>
      </collision>
      <inertial>
        <mass value="0.1"/>
        <origin xyz="0 0 0" rpy="0 0 0"/>
        <inertia ixx="0.0001" ixy="0" ixz="0" iyy="0.0001" iyz="0" izz="0.0001"/>
      </inertial>
    </link>

    <!-- Gripper finger 1 -->
    <link name="${prefix}gripper_finger1_link">
      <visual>
        <geometry>
          <box size="0.01 0.01 0.02"/>
        </geometry>
        <material name="grey">
          <color rgba="0.5 0.5 0.5 1"/>
        </material>
      </visual>
      <collision>
        <geometry>
          <box size="0.01 0.01 0.02"/>
        </geometry>
      </collision>
      <inertial>
        <mass value="0.05"/>
        <origin xyz="0 0 0" rpy="0 0 0"/>
        <inertia ixx="0.00001" ixy="0" ixz="0" iyy="0.00001" iyz="0" izz="0.00001"/>
      </inertial>
    </link>

    <joint name="${prefix}gripper_finger1_joint" type="prismatic">
      <parent link="${prefix}gripper_base_link"/>
      <child link="${prefix}gripper_finger1_link"/>
      <origin xyz="0 0.01 0" rpy="0 0 0"/>
      <axis xyz="0 1 0"/>
      <limit lower="0" upper="0.025" effort="50" velocity="0.1"/>
      <dynamics damping="0.5" friction="0.0"/>
    </joint>

    <!-- Gripper finger 2 -->
    <link name="${prefix}gripper_finger2_link">
      <visual>
        <geometry>
          <box size="0.01 0.01 0.02"/>
        </geometry>
        <material name="grey">
          <color rgba="0.5 0.5 0.5 1"/>
        </material>
      </visual>
      <collision>
        <geometry>
          <box size="0.01 0.01 0.02"/>
        </geometry>
      </collision>
      <inertial>
        <mass value="0.05"/>
        <origin xyz="0 0 0" rpy="0 0 0"/>
        <inertia ixx="0.00001" ixy="0" ixz="0" iyy="0.00001" iyz="0" izz="0.00001"/>
      </inertial>
    </link>

    <joint name="${prefix}gripper_finger2_joint" type="prismatic">
      <parent link="${prefix}gripper_base_link"/>
      <child link="${prefix}gripper_finger2_link"/>
      <origin xyz="0 -0.01 0" rpy="0 0 0"/>
      <axis xyz="0 -1 0"/>
      <limit lower="0" upper="0.025" effort="50" velocity="0.1"/>
      <dynamics damping="0.5" friction="0.0"/>
      <mimic joint="${prefix}gripper_finger1_joint"/>
    </joint>

    <!-- Define transmission for the gripper -->
    <transmission name="${prefix}gripper_trans">
      <type>transmission_interface/SimpleTransmission</type>
      <joint name="${prefix}gripper_finger1_joint">
        <hardwareInterface>hardware_interface/PositionJointInterface</hardwareInterface>
      </joint>
      <actuator name="${prefix}gripper_motor">
        <mechanicalReduction>1</mechanicalReduction>
      </actuator>
    </transmission>
  </xacro:macro>
</robot>