<?xml version="1.0"?>
<robot xmlns:xacro="http://www.ros.org/wiki/xacro">
  <xacro:macro name="ur3_robot" params="prefix joint_limited">
    <xacro:property name="pi" value="3.1415926535897931"/>
    
    <!-- Materials -->
    <material name="UR_Blue">
      <color rgba="0.1 0.1 0.8 1.0"/>
    </material>
    
    <!-- UR3 specific dimensions -->
    <xacro:property name="shoulder_height" value="0.1519"/>
    <xacro:property name="upper_arm_length" value="0.24365"/>
    <xacro:property name="forearm_length" value="0.21325"/>
    <xacro:property name="wrist_1_length" value="0.08535"/>
    <xacro:property name="wrist_2_length" value="0.08535"/>
    <xacro:property name="wrist_3_length" value="0.08195"/>

    <!-- Links -->
    <link name="${prefix}base_link">
      <visual>
        <origin xyz="0 0 0" rpy="0 0 0"/>
        <geometry>
          <mesh filename="package://ur3_pick_place/meshes/collision/base.stl"/>
        </geometry>
        <material name="UR_Blue"/>
      </visual>
      <collision>
        <origin xyz="0 0 0" rpy="0 0 0"/>
        <geometry>
          <mesh filename="package://ur3_pick_place/meshes/collision/base.stl"/>
        </geometry>
      </collision>
    </link>

    <link name="${prefix}shoulder_link">
      <visual>
        <origin xyz="0 0 0" rpy="0 0 0"/>
        <geometry>
          <mesh filename="package://ur3_pick_place/meshes/collision/shoulder.stl"/>
        </geometry>
        <material name="UR_Blue"/>
      </visual>
      <collision>
        <origin xyz="0 0 0" rpy="0 0 0"/>
        <geometry>
          <mesh filename="package://ur3_pick_place/meshes/collision/shoulder.stl"/>
        </geometry>
      </collision>
    </link>

    <link name="${prefix}upper_arm_link">
      <visual>
        <origin xyz="0 0 0" rpy="0 0 0"/>
        <geometry>
          <mesh filename="package://ur3_pick_place/meshes/collision/upperarm.stl"/>
        </geometry>
        <material name="UR_Blue"/>
      </visual>
      <collision>
        <origin xyz="0 0 0" rpy="0 0 0"/>
        <geometry>
          <mesh filename="package://ur3_pick_place/meshes/collision/upperarm.stl"/>
        </geometry>
      </collision>
    </link>

    <link name="${prefix}forearm_link">
      <visual>
        <origin xyz="0 0 0" rpy="0 0 0"/>
        <geometry>
          <mesh filename="package://ur3_pick_place/meshes/collision/forearm.stl"/>
        </geometry>
        <material name="UR_Blue"/>
      </visual>
      <collision>
        <origin xyz="0 0 0" rpy="0 0 0"/>
        <geometry>
          <mesh filename="package://ur3_pick_place/meshes/collision/forearm.stl"/>
        </geometry>
      </collision>
    </link>

    <link name="${prefix}wrist_1_link">
      <visual>
        <origin xyz="0 0 0" rpy="0 0 0"/>
        <geometry>
          <mesh filename="package://ur3_pick_place/meshes/collision/wrist1.stl"/>
        </geometry>
        <material name="UR_Blue"/>
      </visual>
      <collision>
        <origin xyz="0 0 0" rpy="0 0 0"/>
        <geometry>
          <mesh filename="package://ur3_pick_place/meshes/collision/wrist1.stl"/>
        </geometry>
      </collision>
    </link>

    <link name="${prefix}wrist_2_link">
      <visual>
        <origin xyz="0 0 0" rpy="0 0 0"/>
        <geometry>
          <mesh filename="package://ur3_pick_place/meshes/collision/wrist2.stl"/>
        </geometry>
        <material name="UR_Blue"/>
      </visual>
      <collision>
        <origin xyz="0 0 0" rpy="0 0 0"/>
        <geometry>
          <mesh filename="package://ur3_pick_place/meshes/collision/wrist2.stl"/>
        </geometry>
      </collision>
    </link>

    <link name="${prefix}wrist_3_link">
      <visual>
        <origin xyz="0 0 0" rpy="0 0 0"/>
        <geometry>
          <mesh filename="package://ur3_pick_place/meshes/collision/wrist3.stl"/>
        </geometry>
        <material name="UR_Blue"/>
      </visual>
      <collision>
        <origin xyz="0 0 0" rpy="0 0 0"/>
        <geometry>
          <mesh filename="package://ur3_pick_place/meshes/collision/wrist3.stl"/>
        </geometry>
      </collision>
    </link>

    <link name="${prefix}tool0"/>

    <!-- Joints -->
    <joint name="${prefix}shoulder_pan_joint" type="revolute">
      <parent link="${prefix}base_link"/>
      <child link="${prefix}shoulder_link"/>
      <origin xyz="0 0 ${shoulder_height}" rpy="0 0 0"/>
      <axis xyz="0 0 1"/>
      <limit lower="${-2*pi}" upper="${2*pi}" effort="150.0" velocity="3.15"/>
    </joint>

    <joint name="${prefix}shoulder_lift_joint" type="revolute">
      <parent link="${prefix}shoulder_link"/>
      <child link="${prefix}upper_arm_link"/>
      <origin xyz="0 0 0" rpy="0 ${pi/2} 0"/>
      <axis xyz="0 1 0"/>
      <limit lower="${-2*pi}" upper="${2*pi}" effort="150.0" velocity="3.15"/>
    </joint>

    <joint name="${prefix}elbow_joint" type="revolute">
      <parent link="${prefix}upper_arm_link"/>
      <child link="${prefix}forearm_link"/>
      <origin xyz="0 -0.093 ${upper_arm_length}" rpy="0 0 0"/>
      <axis xyz="0 1 0"/>
      <limit lower="${-2*pi}" upper="${2*pi}" effort="150.0" velocity="3.15"/>
      <dynamics damping="0.0" friction="0.0"/>
    </joint>

    <joint name="${prefix}wrist_1_joint" type="revolute">
      <parent link="${prefix}forearm_link"/>
      <child link="${prefix}wrist_1_link"/>
      <origin xyz="0 0 ${forearm_length}" rpy="0 ${pi/2} 0"/>
      <axis xyz="0 1 0"/>
      <limit lower="${-2*pi}" upper="${2*pi}" effort="28.0" velocity="3.2"/>
      <dynamics damping="0.0" friction="0.0"/>
    </joint>

    <joint name="${prefix}wrist_2_joint" type="revolute">
      <parent link="${prefix}wrist_1_link"/>
      <child link="${prefix}wrist_2_link"/>
      <origin xyz="0 0.085 ${wrist_1_length}" rpy="0 0 0"/>
      <axis xyz="0 0 1"/>
      <limit lower="${-2*pi}" upper="${2*pi}" effort="28.0" velocity="3.2"/>
      <dynamics damping="0.0" friction="0.0"/>
    </joint>

    <joint name="${prefix}wrist_3_joint" type="revolute">
      <parent link="${prefix}wrist_2_link"/>
      <child link="${prefix}wrist_3_link"/>
      <origin xyz="0 0 ${wrist_2_length}" rpy="0 0 0"/>
      <axis xyz="0 1 0"/>
      <limit lower="${-2*pi}" upper="${2*pi}" effort="28.0" velocity="3.2"/>
      <dynamics damping="0.0" friction="0.0"/>
    </joint>

    <joint name="${prefix}ee_fixed_joint" type="fixed">
      <parent link="${prefix}wrist_3_link"/>
      <child link="${prefix}tool0"/>
      <origin xyz="0 0.0823 ${wrist_3_length}" rpy="0 0 0"/>
    </joint>

  </xacro:macro>
</robot>