<?xml version="1.0" ?>
<sdf version="1.6">
  <model name="ur3">
    <link name="base_link">
      <pose>0 0 0 0 0 0</pose>
      <inertial>
        <mass>4.0</mass>
        <inertia>
          <ixx>0.00443333156</ixx>
          <ixy>0</ixy>
          <ixz>0</ixz>
          <iyy>0.00443333156</iyy>
          <iyz>0</iyz>
          <izz>0.0072</izz>
        </inertia>
      </inertial>
      <visual name="base_visual">
        <geometry>
          <cylinder>
            <radius>0.06</radius>
            <length>0.05</length>
          </cylinder>
        </geometry>
        <material>
          <ambient>0.7 0.7 0.7 1.0</ambient>
          <diffuse>0.7 0.7 0.7 1.0</diffuse>
          <specular>0.1 0.1 0.1 1.0</specular>
        </material>
      </visual>
      <collision name="base_collision">
        <geometry>
          <cylinder>
            <radius>0.06</radius>
            <length>0.05</length>
          </cylinder>
        </geometry>
      </collision>
    </link>

    <link name="shoulder_link">
      <pose>0 0 0.0675 0 0 0</pose>
      <inertial>
        <mass>3.7</mass>
        <inertia>
          <ixx>0.010267495893</ixx>
          <ixy>0</ixy>
          <ixz>0</ixz>
          <iyy>0.010267495893</iyy>
          <iyz>0</iyz>
          <izz>0.00666</izz>
        </inertia>
      </inertial>
      <visual name="shoulder_visual">
        <geometry>
          <cylinder>
            <radius>0.06</radius>
            <length>0.085</length>
          </cylinder>
        </geometry>
        <material>
          <ambient>0.5 0.5 0.5 1.0</ambient>
          <diffuse>0.5 0.5 0.5 1.0</diffuse>
          <specular>0.1 0.1 0.1 1.0</specular>
        </material>
      </visual>
      <collision name="shoulder_collision">
        <geometry>
          <cylinder>
            <radius>0.06</radius>
            <length>0.085</length>
          </cylinder>
        </geometry>
      </collision>
    </link>

    <joint name="shoulder_pan_joint" type="revolute">
      <parent>base_link</parent>
      <child>shoulder_link</child>
      <axis>
        <xyz>0 0 1</xyz>
        <limit>
          <lower>-3.14159</lower>
          <upper>3.14159</upper>
          <effort>150.0</effort>
          <velocity>3.14159</velocity>
        </limit>
        <dynamics>
          <damping>0.0</damping>
          <friction>0.0</friction>
        </dynamics>
      </axis>
    </joint>

    <link name="upper_arm_link">
      <pose>0 0 0.1525 0 1.5708 0</pose>
      <inertial>
        <mass>8.393</mass>
        <inertia>
          <ixx>0.22689067591</ixx>
          <ixy>0</ixy>
          <ixz>0</ixz>
          <iyy>0.22689067591</iyy>
          <iyz>0</iyz>
          <izz>0.0151074</izz>
        </inertia>
      </inertial>
      <visual name="upper_arm_visual">
        <geometry>
          <cylinder>
            <radius>0.04</radius>
            <length>0.24</length>
          </cylinder>
        </geometry>
        <material>
          <ambient>0.5 0.5 0.5 1.0</ambient>
          <diffuse>0.5 0.5 0.5 1.0</diffuse>
          <specular>0.1 0.1 0.1 1.0</specular>
        </material>
      </visual>
      <collision name="upper_arm_collision">
        <geometry>
          <cylinder>
            <radius>0.04</radius>
            <length>0.24</length>
          </cylinder>
        </geometry>
      </collision>
    </link>

    <joint name="shoulder_lift_joint" type="revolute">
      <parent>shoulder_link</parent>
      <child>upper_arm_link</child>
      <axis>
        <xyz>0 1 0</xyz>
        <limit>
          <lower>-3.14159</lower>
          <upper>3.14159</upper>
          <effort>150.0</effort>
          <velocity>3.14159</velocity>
        </limit>
        <dynamics>
          <damping>0.0</damping>
          <friction>0.0</friction>
        </dynamics>
      </axis>
    </joint>

    <link name="forearm_link">
      <pose>0 0 0.3925 0 0 0</pose>
      <inertial>
        <mass>2.275</mass>
        <inertia>
          <ixx>0.049443313556</ixx>
          <ixy>0</ixy>
          <ixz>0</ixz>
          <iyy>0.049443313556</iyy>
          <iyz>0</iyz>
          <izz>0.004095</izz>
        </inertia>
      </inertial>
      <visual name="forearm_visual">
        <geometry>
          <cylinder>
            <radius>0.03</radius>
            <length>0.215</length>
          </cylinder>
        </geometry>
        <material>
          <ambient>0.5 0.5 0.5 1.0</ambient>
          <diffuse>0.5 0.5 0.5 1.0</diffuse>
          <specular>0.1 0.1 0.1 1.0</specular>
        </material>
      </visual>
      <collision name="forearm_collision">
        <geometry>
          <cylinder>
            <radius>0.03</radius>
            <length>0.215</length>
          </cylinder>
        </geometry>
      </collision>
    </link>

    <joint name="elbow_joint" type="revolute">
      <parent>upper_arm_link</parent>
      <child>forearm_link</child>
      <axis>
        <xyz>0 1 0</xyz>
        <limit>
          <lower>-3.14159</lower>
          <upper>3.14159</upper>
          <effort>150.0</effort>
          <velocity>3.14159</velocity>
        </limit>
        <dynamics>
          <damping>0.0</damping>
          <friction>0.0</friction>
        </dynamics>
      </axis>
    </joint>

    <link name="wrist_1_link">
      <pose>0 0 0.6025 0 0 0</pose>
      <inertial>
        <mass>1.219</mass>
        <inertia>
          <ixx>0.011752971225</ixx>
          <ixy>0</ixy>
          <ixz>0</ixz>
          <iyy>0.011752971225</iyy>
          <iyz>0</iyz>
          <izz>0.0021942</izz>
        </inertia>
      </inertial>
      <visual name="wrist_1_visual">
        <geometry>
          <cylinder>
            <radius>0.03</radius>
            <length>0.08</length>
          </cylinder>
        </geometry>
        <material>
          <ambient>0.5 0.5 0.5 1.0</ambient>
          <diffuse>0.5 0.5 0.5 1.0</diffuse>
          <specular>0.1 0.1 0.1 1.0</specular>
        </material>
      </visual>
      <collision name="wrist_1_collision">
        <geometry>
          <cylinder>
            <radius>0.03</radius>
            <length>0.08</length>
          </cylinder>
        </geometry>
      </collision>
    </link>

    <joint name="wrist_1_joint" type="revolute">
      <parent>forearm_link</parent>
      <child>wrist_1_link</child>
      <axis>
        <xyz>0 1 0</xyz>
        <limit>
          <lower>-3.14159</lower>
          <upper>3.14159</upper>
          <effort>28.0</effort>
          <velocity>3.14159</velocity>
        </limit>
        <dynamics>
          <damping>0.0</damping>
          <friction>0.0</friction>
        </dynamics>
      </axis>
    </joint>

    <link name="wrist_2_link">
      <pose>0 0 0.6525 0 0 0</pose>
      <inertial>
        <mass>1.219</mass>
        <inertia>
          <ixx>0.011752971225</ixx>
          <ixy>0</ixy>
          <ixz>0</ixz>
          <iyy>0.011752971225</iyy>
          <iyz>0</iyz>
          <izz>0.0021942</izz>
        </inertia>
      </inertial>
      <visual name="wrist_2_visual">
        <geometry>
          <cylinder>
            <radius>0.03</radius>
            <length>0.08</length>
          </cylinder>
        </geometry>
        <material>
          <ambient>0.5 0.5 0.5 1.0</ambient>
          <diffuse>0.5 0.5 0.5 1.0</diffuse>
          <specular>0.1 0.1 0.1 1.0</specular>
        </material>
      </visual>
      <collision name="wrist_2_collision">
        <geometry>
          <cylinder>
            <radius>0.03</radius>
            <length>0.08</length>
          </cylinder>
        </geometry>
      </collision>
    </link>

    <joint name="wrist_2_joint" type="revolute">
      <parent>wrist_1_link</parent>
      <child>wrist_2_link</child>
      <axis>
        <xyz>0 0 1</xyz>
        <limit>
          <lower>-3.14159</lower>
          <upper>3.14159</upper>
          <effort>28.0</effort>
          <velocity>3.14159</velocity>
        </limit>
        <dynamics>
          <damping>0.0</damping>
          <friction>0.0</friction>
        </dynamics>
      </axis>
    </joint>

    <link name="wrist_3_link">
      <pose>0 0 0.7125 0 0 0</pose>
      <inertial>
        <mass>0.1879</mass>
        <inertia>
          <ixx>0.0001</ixx>
          <ixy>0</ixy>
          <ixz>0</ixz>
          <iyy>0.0001</iyy>
          <iyz>0</iyz>
          <izz>0.0001</izz>
        </inertia>
      </inertial>
      <visual name="wrist_3_visual">
        <geometry>
          <cylinder>
            <radius>0.03</radius>
            <length>0.05</length>
          </cylinder>
        </geometry>
        <material>
          <ambient>0.5 0.5 0.5 1.0</ambient>
          <diffuse>0.5 0.5 0.5 1.0</diffuse>
          <specular>0.1 0.1 0.1 1.0</specular>
        </material>
      </visual>
      <collision name="wrist_3_collision">
        <geometry>
          <cylinder>
            <radius>0.03</radius>
            <length>0.05</length>
          </cylinder>
        </geometry>
      </collision>
    </link>

    <joint name="wrist_3_joint" type="revolute">
      <parent>wrist_2_link</parent>
      <child>wrist_3_link</child>
      <axis>
        <xyz>0 1 0</xyz>
        <limit>
          <lower>-3.14159</lower>
          <upper>3.14159</upper>
          <effort>28.0</effort>
          <velocity>3.14159</velocity>
        </limit>
        <dynamics>
          <damping>0.0</damping>
          <friction>0.0</friction>
        </dynamics>
      </axis>
    </joint>

    <link name="ee_link">
      <pose>0 0 0.7425 0 0 0</pose>
      <inertial>
        <mass>0.001</mass>
        <inertia>
          <ixx>0.0001</ixx>
          <ixy>0</ixy>
          <ixz>0</ixz>
          <iyy>0.0001</iyy>
          <iyz>0</iyz>
          <izz>0.0001</izz>
        </inertia>
      </inertial>
      <visual name="ee_visual">
        <geometry>
          <box>
            <size>0.02 0.02 0.02</size>
          </box>
        </geometry>
        <material>
          <ambient>1.0 0.0 0.0 1.0</ambient>
          <diffuse>1.0 0.0 0.0 1.0</diffuse>
          <specular>0.1 0.1 0.1 1.0</specular>
        </material>
      </visual>
    </link>

    <joint name="ee_joint" type="fixed">
      <parent>wrist_3_link</parent>
      <child>ee_link</child>
    </joint>
  </model>
</sdf>
